<?xml version="1.0"?>
<robot name="two_link_robot">

  <link name="base_link">
    <visual>
      <origin xyz="0 0 0.3" rpy="0 0 0"/>
      <geometry>
        <cylinder length="0.006" radius="0.2"/>
      </geometry>
      <material name="blue">
        <color rgba="0 0 1 1"/>
      </material>
    </visual>
    <collision>
      <origin xyz="0 0 0.3" rpy="0 0 0"/>
      <geometry>
        <cylinder length="0.6" radius="0.2"/>
      </geometry>
    </collision>
    <inertial>
      <origin xyz="0 0 0.3" rpy="0 0 0"/>
      <mass value="1.0"/>
      <inertia ixx="0.01" ixy="0" ixz="0" iyy="0.01" iyz="0" izz="0.02"/>
    </inertial>
  </link>

  <link name="second_link">
    <visual>
      <origin xyz="0 0.2 0.9" rpy="0 0 0"/>
      <geometry>
        <mesh filename="package://articubot_one/meshes/base_link.stl" scale="1 1 1"/>
      </geometry>
    </visual>
    <collision>
      <origin xyz="0 0.2 0.9" rpy="0 0 0"/>
      <geometry>
        <mesh filename="package://articubot_one/meshes/base_link.stl" scale="1 1 1"/>
      </geometry>
    </collision>
    <inertial>
      <origin xyz="0 0.2 0.9" rpy="0 0 0"/>
      <mass value="0.5"/>
      <inertia ixx="0.005" ixy="0" ixz="0" iyy="0.005" iyz="0" izz="0.01"/>
    </inertial>
  </link>

  <joint name="joint1" type="revolute">
    <parent link="base_link"/>
    <child link="second_link"/>
    <origin xyz="0 0 0.6" rpy="0 0 0"/>
    <axis xyz="0 0 1"/>
    <limit lower="-1.57" upper="1.57" effort="1000" velocity="1.0"/>
  </joint>

</robot>
