<robot name="simple_box">

  <link name="base_link">
    <inertial>
      <origin xyz="2 0 0" />
      <mass value="1.0" />
      <inertia  ixx="1.0" ixy="0.0"  ixz="0.0"  iyy="100.0"  iyz="0.0"  izz="1.0" />
    </inertial>
    <visual>
      <origin xyz="2 0 1"/>
      <geometry>
        <box size="1 1 2" />
      </geometry>
    </visual>
    <collision>
      <origin xyz="2 0 1"/>
      <geometry>
        <box size="1 1 2" />
      </geometry>
    </collision>
  </link>
  <gazebo reference="my_box">
    <material>Gazebo/Blue</material>
  </gazebo>
  
  <link name="my_box2">
    <inertial>
      <origin xyz="2 0 0" />
      <mass value="1.0" />
      <inertia  ixx="1.0" ixy="0.0"  ixz="0.0"  iyy="100.0"  iyz="0.0"  izz="1.0" />
    </inertial>
    <visual>
      <origin xyz="2 0 1"/>
      <geometry>
        <box size="1 1 2" />
      </geometry>
    </visual>
    <collision>
      <origin xyz="2 0 1"/>
      <geometry>
        <box size="1 1 2" />
      </geometry>
    </collision>
  </link>
  <gazebo reference="my_box2">
    <material>Gazebo/Blue</material>
  </gazebo> 

  <link name="my_box3">
    <inertial>
      <origin xyz="2 0 0" />
      <mass value="1.0" />
      <inertia  ixx="1.0" ixy="0.0"  ixz="0.0"  iyy="100.0"  iyz="0.0"  izz="1.0" />
    </inertial>
    <visual>
      <origin xyz="2 0 1"/>
      <geometry>
        <box size="1 1 2" />
      </geometry>
    </visual>
    <collision>
      <origin xyz="2 0 1"/>
      <geometry>
        <box size="1 1 2" />
      </geometry>
    </collision>
  </link>
  <gazebo reference="my_box3">
    <material>Gazebo/Blue</material>
  </gazebo>  
  
  <!-- Joints -->
  

  <joint name="box_joint" type="revolute">
    <parent link="base_link"/>
    <child link="my_box2"/>
    <origin xyz="0 0 0.05" rpy="0 0 0"/>
    <limit lower="-1.57" upper="1.57" effort="100.0" velocity="0.5"/>
  </joint>

  <joint name="box_joint2" type="revolute">
    <parent link="my_box2"/>
    <child link="my_box3"/>
    <origin xyz="0 0 0.05" rpy="0 0 0"/>
    <limit lower="-1.57" upper="1.57" effort="100.0" velocity="0.5"/>
  </joint>
  
</robot>
