<?xml version="1.0" ?>
<!-- =================================================================================== -->
<!-- |    This document was autogenerated by xacro from robot.urdf.xacro               | -->
<!-- |    EDITING THIS FILE BY HAND IS NOT RECOMMENDED                                 | -->
<!-- =================================================================================== -->
<robot name="robot_bob">
  <!-- Materials -->
  <material name="white">
    <color rgba="1 1 1 1"/>
  </material>
  <material name="orange">
    <color rgba="1 0.3 0.1 1"/>
  </material>
  <material name="blue">
    <color rgba="0.2 0.2 1 1"/>
  </material>
  <material name="black">
    <color rgba="0 0 0 1"/>
  </material>
  <!-- Links -->
  <!-- Base Link -->
  <link name="base_link">
    <visual>
      <origin xyz="0 0 0"/>
      <geometry>
        <box size="0.1 0.1 0.1"/>
      </geometry>
    </visual>
  </link>
  <gazebo reference="base_link">
    <material>Gazebo/Red</material>
  </gazebo>
  <!-- Chassis -->
  <joint name="chassis_joint" type="fixed">
    <parent link="base_link"/>
    <child link="chassis"/>
    <origin xyz="-0.1 0 0"/>
    <limit effort="100.0" lower="-1.57" upper="1.57" velocity="0.5"/>
  </joint>
  <link name="chassis">
    <visual>
      <origin xyz="0.15 0 0.075"/>
      <geometry>
        <box size="0.3 0.3 0.15"/>
      </geometry>
      <material name="white"/>
    </visual>
    <collision>
      <origin xyz="0.15 0 0.075"/>
      <geometry>
        <box size="0.3 0.3 0.15"/>
      </geometry>
    </collision>
    <inertial>
      <mass value="1.0"/>
      <inertia ixx="0.009374999999999998" ixy="0.0" ixz="0.0" iyy="0.009374999999999998" iyz="0.0" izz="0.015"/>
      <origin rpy="0 0 0" xyz="0.15 0 0.75"/>
    </inertial>
  </link>
  <gazebo reference="chassis">
    <material>Gazebo/White</material>
  </gazebo>
  <!-- Left Wheel -->
  <joint name="left_wheel_joint" type="continuous">
    <parent link="base_link"/>
    <child link="left_wheel"/>
    <origin rpy="-1.5707963267948966 0 0" xyz="0.0 0.175 0.0"/>
    <axis xyz="0 0 1"/>
    <limit effort="100.0" lower="-1.57" upper="1.57" velocity="0.5"/>
  </joint>
  <link name="left_wheel">
    <visual>
      <geometry>
        <cylinder length="0.04" radius="0.05"/>
      </geometry>
      <material name="blue"/>
    </visual>
    <collision>
      <geometry>
        <cylinder length="0.04" radius="0.05"/>
      </geometry>
    </collision>
    <inertial>
      <mass value="0.1"/>
      <inertia ixx="7.583333333333335e-05" ixy="0.0" ixz="0.0" iyy="7.583333333333335e-05" iyz="0.0" izz="0.00012500000000000003"/>
      <origin rpy="0 0 0" xyz="0 0 0"/>
    </inertial>
  </link>
  <gazebo reference="left_wheel">
    <material>Gazebo/Blue</material>
  </gazebo>
  <!-- Right Wheel -->
  <joint name="right_wheel_joint" type="continuous">
    <parent link="base_link"/>
    <child link="right_wheel"/>
    <origin rpy="1.5707963267948966 0 0" xyz="0.0 -0.175 0.0"/>
    <axis xyz="0 0 -1"/>
    <limit effort="100.0" lower="-1.57" upper="1.57" velocity="0.5"/>
  </joint>
  <link name="right_wheel">
    <visual>
      <geometry>
        <cylinder length="0.04" radius="0.05"/>
      </geometry>
      <material name="blue"/>
    </visual>
    <collision>
      <geometry>
        <cylinder length="0.04" radius="0.05"/>
      </geometry>
    </collision>
    <inertial>
      <mass value="0.1"/>
      <inertia ixx="7.583333333333335e-05" ixy="0.0" ixz="0.0" iyy="7.583333333333335e-05" iyz="0.0" izz="0.00012500000000000003"/>
      <origin rpy="0 0 0" xyz="0 0 0"/>
    </inertial>
  </link>
  <gazebo reference="right_wheel">
    <material>Gazebo/Blue</material>
  </gazebo>
  <!-- Caster Wheel -->
  <joint name="caster_wheel_joint" type="fixed">
    <parent link="base_link"/>
    <child link="caster"/>
    <origin rpy="-1.5707963267948966 0 0" xyz="0.2 0 0"/>
  </joint>
  <link name="caster">
    <visual>
      <geometry>
        <sphere radius="0.05"/>
      </geometry>
      <material name="orange"/>
    </visual>
    <collision>
      <geometry>
        <sphere radius="0.05"/>
      </geometry>
    </collision>
    <inertial>
      <mass value="0.1"/>
      <inertia ixx="0.00010000000000000005" ixy="0.0" ixz="0.0" iyy="0.00010000000000000005" iyz="0.0" izz="0.00010000000000000005"/>
      <origin rpy="0 0 0" xyz="0 0 0"/>
    </inertial>
  </link>
  <gazebo reference="caster">
    <material>Gazebo/Orange</material>
  </gazebo>
  <gazebo>
    <plugin filename="libgazebo_ros_diff_drive.so" name="my_diff_drive">
      <!-- Wheel Information -->
      <left_joint>left_wheel_joint</left_joint>
      <right_joint>right_wheel_joint</right_joint>
      <wheel_separation>0.297</wheel_separation>
      <wheel_diameter>0.066</wheel_diameter>
      <!-- Limits -->
      <max_wheel_torque>200</max_wheel_torque>
      <max_wheel_acceleration>10.0</max_wheel_acceleration>
      <!-- Output -->
      <odometry_frame>odom</odometry_frame>
      <robot_base_frame>base_link</robot_base_frame>
      <publish_odom>true</publish_odom>
      <publish_odom_tf>true</publish_odom_tf>
      <publish_wheel_tf>true</publish_wheel_tf>
    </plugin>
  </gazebo>
</robot>
