<?xml version="1.0"?>
<robot xmlns:xacro="http://www.ros.org/wiki/xacro" name = "bob1">


<!-- Materials -->
    <material name = "white">
        <color rgba= "1 1 1 1"/>
    </material>   
    <material name = "orange">
        <color rgba= "1 0.3 0.1 1"/>
    </material>
    <material name = "blue">
        <color rgba= "0.2 0.2 1 1"/>
    </material>
    <material name = "black">
        <color rgba= "0 0 0 1"/>
    </material>

<!-- Links -->

<!-- Base Link -->
  <link name="base_link">
    <visual>
      <origin xyz="0 0 0"/>
      <geometry>
        <box size="0.1 0.1 0.1" />
      </geometry>
    </visual>
  </link>
  <gazebo reference="base_link">
    <material>Gazebo/Red</material>
  </gazebo>
  
<!-- Chassis -->
    <joint name = "chassis_joint" type="fixed">
        <parent link = "base_link"/>
        <child link = "chassis"/>
        <origin xyz= "-0.1 0 0"/>
    	<limit lower="-1.57" upper="1.57" effort="100.0" velocity="0.5"/>
    </joint>

    <link name = "chassis">
        <visual>
            <origin xyz= "0.15 0 0.075" />
            <geometry>
                <box size= "0.3 0.3 0.15" />
            </geometry>
            <material name="white"/>
        </visual>
        <collision>
            <origin xyz= "0.15 0 0.075" />
            <geometry>
                <box size= "0.3 0.3 0.15" />
            </geometry>
        </collision>
        <inertial>
            <mass value="1.0" />
            <inertia ixx="${(1/12) * 1.0 * (0.3 *0.3 +0.15*0.15)}" ixy="0.0" ixz="0.0"
                    iyy="${(1/12) * 1.0 * (0.3 *0.3 +0.15*0.15)}" iyz="0.0"
                    izz="${(1/12) * 1.0 * (0.3 *0.3 +0.3 *0.3 )}" />
            <origin xyz = "0.15 0 0.75" rpy = "0 0 0"/>
        </inertial>
    </link>
  <gazebo reference="chassis">
    <material>Gazebo/White</material>
  </gazebo>

<!-- Left Wheel -->
    <joint name = "left_wheel_joint" type = "continuous" >
        <parent link="base_link"/>
        <child link="left_wheel"/>
        <origin xyz= "0.0 0.175 0.0" rpy="-${pi/2} 0 0" />
        <axis xyz = "0 0 1"/>
    	<limit lower="-1.57" upper="1.57" effort="100.0" velocity="0.5"/>
    </joint>

    <link name="left_wheel">
        <visual>
            <geometry>
                <cylinder radius="0.05" length = "0.04"/>
            </geometry>
            <material name="blue"/>
        </visual>
        <collision>
            <geometry>
                <cylinder radius="0.05" length = "0.04"/>
            </geometry>
        </collision>
        <inertial>
            <mass value="0.1" />
            <inertia ixx="${(1/12) * 0.1 * (3*.05*.05 + 0.04*0.04)}" ixy="0.0" ixz="0.0"
                    iyy="${(1/12) * 0.1 * (3*.05*.05 + 0.04*0.04)}" iyz="0.0"
                    izz="${(1/2) * 0.1 * (.05*.05)}" />
            <origin xyz = "0 0 0" rpy = "0 0 0"/>
        </inertial>
    </link>
  <gazebo reference="left_wheel">
    <material>Gazebo/Blue</material>
  </gazebo>


    <!-- Right Wheel -->
    <joint name = "right_wheel_joint" type = "continuous" >
        <parent link="base_link"/>
        <child link="right_wheel"/>
        <origin xyz= "0.0 -0.175 0.0" rpy="${pi/2} 0 0" />
        <axis xyz = "0 0 -1"/>
    	<limit lower="-1.57" upper="1.57" effort="100.0" velocity="0.5"/>
    </joint>

    <link name="right_wheel">
        <visual>
            <geometry>
                <cylinder radius="0.05" length = "0.04"/>
            </geometry>
            <material name="blue"/>
        </visual>
        <collision>
            <geometry>
                <cylinder radius="0.05" length = "0.04"/>
            </geometry>
        </collision>
        <inertial>
            <mass value="0.1" />
            <inertia ixx="${(1/12) * 0.1 * (3*.05*.05 + 0.04*0.04)}" ixy="0.0" ixz="0.0"
                    iyy="${(1/12) * 0.1 * (3*.05*.05 + 0.04*0.04)}" iyz="0.0"
                    izz="${(1/2) * 0.1 * (.05*.05)}" />
            <origin xyz = "0 0 0" rpy = "0 0 0"/>
        </inertial>
    </link>
  <gazebo reference="right_wheel">
    <material>Gazebo/Blue</material>
  </gazebo>

    <!-- Caster Wheel -->
    <joint name = "caster_wheel_joint" type ="fixed" >
        <parent link = "base_link"/>
        <child link = "caster" />
        <origin xyz = "0.2 0 0" rpy = "-${pi/2} 0 0" />
    </joint>

    <link name = "caster">
        <visual>
            <geometry>
                <sphere radius="0.05"/>
            </geometry>
            <material name = "orange"/>
        </visual>
        <collision>
            <geometry>
                <sphere radius="0.05"/>
            </geometry>
        </collision>
        <inertial>
            <mass value="0.1" />
            <inertia ixx="${(2/5) * 0.1 * (0.05*0.05)}" ixy="0.0" ixz="0.0"
                    iyy="${(2/5) * 0.1 * (0.05*0.05)}" iyz="0.0"
                    izz="${(2/5) * 0.1 * (0.05*0.05)}" />
            <origin xyz = "0 0 0" rpy = "0 0 0"/>
        </inertial>
    </link>
  <gazebo reference="caster">
    <material>Gazebo/Orange</material>
  </gazebo>

  

</robot>
